2018-04-02 10:44:08,946 : Machine : Mission Pinball Framework Core Engine v0.33.49
2018-04-02 10:44:08,946 : Machine : Command line arguments: {'loglevel': 11, 'no_load_cache': False, 'mc_file_name': None, 'force_assets_load': False, 'force_platform': None, 'mpfconfigfile': 'c:\\python34\\lib\\site-packages\\mpf\\mpfconfig.yaml', 'create_config_cache': True, 'bcp': True, 'pause': False, 'logfile': 'logs\\2018-04-02-10-44-08-mpf-DESKTOP-U1P21TS.log', 'configfile': ['config'], 'consoleloglevel': 20, 'syslog_address': None}
2018-04-02 10:44:08,946 : Machine : MPF path: c:\python34\lib\site-packages\mpf
2018-04-02 10:44:08,947 : Machine : Machine path: D:\Dev\mpf\scottp
2018-04-02 10:44:08,947 : Machine : Platform: win32
2018-04-02 10:44:08,947 : Machine : Python executable location: c:\python34\python.exe
2018-04-02 10:44:08,947 : Machine : Python version: 3.4.4 (64-bit)
2018-04-02 10:44:09,117 : Machine : Loading config from original files
2018-04-02 10:44:09,166 : Machine : Machine config file #1: D:\Dev\mpf\scottp\config\config
2018-04-02 10:44:09,169 : root : YAML error found in file D:\Dev\mpf\scottp\config\config.yml. Line 30, Position 2
Traceback (most recent call last):
  File "c:\python34\lib\site-packages\mpf\file_interfaces\yaml_interface.py", line 272, in load
    config = YamlInterface.process(f, round_trip)
  File "c:\python34\lib\site-packages\mpf\file_interfaces\yaml_interface.py", line 303, in process
    return Util.keys_to_lower(yaml.load(data_string, Loader=MpfLoader))
  File "c:\python34\lib\site-packages\ruamel\yaml\main.py", line 75, in load
    return loader.get_single_data()
  File "c:\python34\lib\site-packages\ruamel\yaml\constructor.py", line 57, in get_single_data
    node = self.get_single_node()
  File "c:\python34\lib\site-packages\ruamel\yaml\composer.py", line 46, in get_single_node
    document = self.compose_document()
  File "c:\python34\lib\site-packages\ruamel\yaml\composer.py", line 66, in compose_document
    node = self.compose_node(None, None)
  File "c:\python34\lib\site-packages\ruamel\yaml\composer.py", line 97, in compose_node
    node = self.compose_mapping_node(anchor)
  File "c:\python34\lib\site-packages\ruamel\yaml\composer.py", line 149, in compose_mapping_node
    while not self.check_event(MappingEndEvent):
  File "c:\python34\lib\site-packages\ruamel\yaml\parser_.py", line 118, in check_event
    self.current_event = self.state()
  File "c:\python34\lib\site-packages\ruamel\yaml\parser_.py", line 504, in parse_block_mapping_key
    token.start_mark)
ruamel.yaml.parser_.ParserError: while parsing a block mapping
  in "D:\Dev\mpf\scottp\config\config.yml", line 3, column 1
expected <block end>, but found '<block mapping start>'
  in "D:\Dev\mpf\scottp\config\config.yml", line 30, column 2

During handling of the above exception, another exception occurred:

Traceback (most recent call last):
  File "c:\python34\lib\site-packages\mpf\commands\game.py", line 181, in __init__
    MachineController(mpf_path, machine_path, vars(args)).run()
  File "c:\python34\lib\site-packages\mpf\core\machine.py", line 96, in __init__
    self._load_config()
  File "c:\python34\lib\site-packages\mpf\core\machine.py", line 414, in _load_config
    self._load_config_from_files()
  File "c:\python34\lib\site-packages\mpf\core\machine.py", line 434, in _load_config_from_files
    config_type='machine'))
  File "c:\python34\lib\site-packages\mpf\core\config_processor.py", line 24, in load_config_file
    config = FileManager.load(filename, verify_version, halt_on_error)
  File "c:\python34\lib\site-packages\mpf\core\file_manager.py", line 165, in load
    round_trip)
  File "c:\python34\lib\site-packages\mpf\file_interfaces\yaml_interface.py", line 281, in load
    "Position {}".format(filename, mark.line + 1, mark.column + 1))
ValueError: YAML error found in file D:\Dev\mpf\scottp\config\config.yml. Line 30, Position 2
